Spark Optimization Logs - 2025-08-25 07:17:56.624821
================================================================================

Starting: 12 cores, 64 partitions
--------------------------------------------------
ERROR:root:Exception while sending command.
Traceback (most recent call last):
  File "/usr/local/spark/python/lib/py4j-0.10.9.7-src.zip/py4j/clientserver.py", line 511, in send_command
    answer = smart_decode(self.stream.readline()[:-1])
                          ~~~~~~~~~~~~~~~~~~~~^^
RuntimeError: reentrant call inside <_io.BufferedReader name=61>

During handling of the above exception, another exception occurred:

Traceback (most recent call last):
  File "/usr/local/spark/python/lib/py4j-0.10.9.7-src.zip/py4j/java_gateway.py", line 1038, in send_command
    response = connection.send_command(command)
  File "/usr/local/spark/python/lib/py4j-0.10.9.7-src.zip/py4j/clientserver.py", line 539, in send_command
    raise Py4JNetworkError(
        "Error while sending or receiving", e, proto.ERROR_ON_RECEIVE)
py4j.protocol.Py4JNetworkError: Error while sending or receiving
ERROR:root:Exception while sending command.
Traceback (most recent call last):
  File "/usr/local/spark/python/lib/py4j-0.10.9.7-src.zip/py4j/clientserver.py", line 511, in send_command
    answer = smart_decode(self.stream.readline()[:-1])
                          ~~~~~~~~~~~~~~~~~~~~^^
  File "/opt/miniconda3/lib/python3.13/socket.py", line 719, in readinto
    return self._sock.recv_into(b)
           ~~~~~~~~~~~~~~~~~~~~^^^
  File "/usr/local/spark/python/pyspark/context.py", line 381, in signal_handler
    self.cancelAllJobs()
    ~~~~~~~~~~~~~~~~~~^^
  File "/usr/local/spark/python/pyspark/context.py", line 2446, in cancelAllJobs
    self._jsc.sc().cancelAllJobs()
    ~~~~~~~~~~~~^^
  File "/usr/local/spark/python/lib/py4j-0.10.9.7-src.zip/py4j/java_gateway.py", line 1322, in __call__
    return_value = get_return_value(
        answer, self.gateway_client, self.target_id, self.name)
  File "/usr/local/spark/python/pyspark/errors/exceptions/captured.py", line 179, in deco
    return f(*a, **kw)
  File "/usr/local/spark/python/lib/py4j-0.10.9.7-src.zip/py4j/protocol.py", line 334, in get_return_value
    raise Py4JError(
        "An error occurred while calling {0}{1}{2}".
        format(target_id, ".", name))
py4j.protocol.Py4JError: An error occurred while calling o40.sc

During handling of the above exception, another exception occurred:

Traceback (most recent call last):
  File "/usr/local/spark/python/lib/py4j-0.10.9.7-src.zip/py4j/java_gateway.py", line 1038, in send_command
    response = connection.send_command(command)
  File "/usr/local/spark/python/lib/py4j-0.10.9.7-src.zip/py4j/clientserver.py", line 539, in send_command
    raise Py4JNetworkError(
        "Error while sending or receiving", e, proto.ERROR_ON_RECEIVE)
py4j.protocol.Py4JNetworkError: Error while sending or receiving
